Workbook

Sheet Unread
A1: Book Ranking
A2: Title | B2: Potential | C2: In Trello | D2: Media | E2: Value | F2: Page Numbers | G2: Result | H2: Read
A3: The Rubaiyat | E3: 4 | F3: 46 | G3: =E3/F3 -> 0.086956522 | H3: Yes
A4: World War I at Home | E4: 2 | G4: =IFERROR(E4/F4," ") | H4: No
A5: World War I (Baldwin) | E5: 2 | G5: =IFERROR(E5/F5," ") | H5: No
A6: Cavalry of the Clouds | E6: 2 | G6: =IFERROR(E6/F6," ") | H6: No
A7: Undertones of War | E7: 2 | G7: =IFERROR(E7/F7," ") | H7: No
A8: Sinking of the Titanic | E8: 2 | G8: =IFERROR(E8/F8," ") | H8: No
A9: History of the World War (March) | E9: 2 | G9: =IFERROR(E9/F9," ") | H9: No
A10: World War for Humanity | E10: 2 | G10: =IFERROR(E10/F10," ") | H10: No
A11: School for Soldiers | E11: 2 | G11: =IFERROR(E11/F11," ") | H11: No
A12: The First World War (Strachan) | E12: 2 | G12: =IFERROR(E12/F12," ") | H12: No
A13: Soldier from the Wars Returning (Carrington) | E13: 2 | G13: =IFERROR(E13/F13," ") | H13: No
A14: Randomness and Mathematical Proof (Report) | E14: 4 | F14: 9 | G14: =IFERROR(E14/F14," ") -> 0.44444444 | H14: Yes
A15: Enhancing our Grasp of Complex Arguments (Paper) | D15: Online Article | E15: 4 | F15: 11 | G15: =IFERROR(E15/F15," ") -> 0.36363636 | H15: Yes
A16: Algorithmic Accountability: On the Investigation of Black Boxes | D16: Online Article | E16: 4 | F16: 14 | G16: =IFERROR(E16/F16," ") -> 0.28571429 | H16: No
A17: Algorithmic bias (W) | D17: Wikipedia | E17: 3 | F17: 12 | G17: =IFERROR(E17/F17," ") -> 0.25 | H17: No
A18: The Waste Land: Poem | D18: Online Text | E18: 3 | F18: 14 | G18: =IFERROR(E18/F18," ") -> 0.21428571 | H18: Yes
A19: Zoar (Pamphlet) | E19: 5 | F19: 73 | G19: =E19/F19 -> 0.068493151 | H19: Yes
A20: Wisdom and the Context of Knowledge: Knowing that One Doesn't Know: Meacham (Report) | D20: Online Text | E20: 4 | F20: 20 | G20: =IFERROR(E20/F20," ") -> 0.2 | H20: No
A21: Dhammapada | D21: Wikipedia | E21: 5 | F21: 29 | G21: =IFERROR(E21/F21," ") -> 0.17241379 | H21: No
A22: Self-organised criticality-what it is and what it isn't (Report) | D22: Research Paper | E22: 3 | F22: 20 | G22: =IFERROR(E22/F22," ") -> 0.15 | H22: No
A23: Power laws, Pareto distributinos and Zipf's Law (Report) | D23: Research Paper | E23: 3 | F23: 25 | G23: =IFERROR(E23/F23," ") -> 0.12 | H23: No
A24: On the Decay of the Art of Lying | B24: y | D24: Book | E24: 2 | F24: 30 | G24: =E24/F24 -> 0.066666667 | H24: No
A25: A Mathematica Theory of Communication: CE Shannon (Report) | D25: Research Paper | E25: 3 | F25: 55 | G25: =IFERROR(E25/F25," ") -> 0.054545455 | H25: No
A26: Guerilla Warfare Mao | B26: y | D26: Book | E26: 4 | F26: 74 | G26: =IFERROR(E26/F26," ") -> 0.054054054 | H26: No
A27: Thermodynamics | B27: y | D27: Book | E27: 5 | F27: 120 | G27: =IFERROR(E27/F27," ") -> 0.041666667 | H27: No
A28: Campaigns of General Custer | B28: y | D28: Book | E28: 3 | F28: 72 | G28: =IFERROR(E28/F28," ") -> 0.041666667 | H28: No
A29: A Monk's Guide to a Clean House | B29: y | D29: Book | E29: 5 | F29: 128 | G29: =IFERROR(E29/F29," ") -> 0.0390625 | H29: No
A30: Maneuver Warfare Handbook | B30: y | D30: Book | E30: 5 | F30: 133 | G30: =IFERROR(E30/F30," ") -> 0.037593985 | H30: No
A31: Drop the Rock: Removing Character Defects - Steps Six and Seven | B31: y | D31: Book | E31: 4 | F31: 132 | G31: =IFERROR(E31/F31," ") -> 0.03030303 | H31: No
A32: The Parent's Tao Te Ching | B32: y | D32: Book | E32: 4 | F32: 160 | G32: =IFERROR(E32/F32," ") -> 0.025 | H32: No
A33: The Gnosis of the Light | B33: y | D33: Book | E33: 2 | F33: 80 | G33: =IFERROR(E33/F33," ") -> 0.025 | H33: No
A34: The Elements of Zen | B34: y | D34: Book | E34: 3 | F34: 124 | G34: =IFERROR(E34/F34," ") -> 0.024193548 | H34: No
A35: Impeachment: A Citizen's Guide | B35: y | D35: Book | E35: 5 | F35: 208 | G35: =IFERROR(E35/F35," ") -> 0.024038462 | H35: No
A36: On Tyranny: Twenty Lessons From the Twentieth Century | B36: y | D36: Book | E36: 3 | F36: 128 | G36: =IFERROR(E36/F36," ") -> 0.0234375 | H36: No
A37: Advice Not Given: A Guide for Getting Over Yourself | B37: y | D37: Book | E37: 5 | F37: 224 | G37: =IFERROR(E37/F37," ") -> 0.022321429 | H37: No
A38: Left of Bang: How the Marine Corps' Combat Hunter Program Can Save Your Life | B38: y | D38: Book | E38: 5 | F38: 228 | G38: =IFERROR(E38/F38," ") -> 0.021929825 | H38: No
A39: Markings (Dag) | D39: Book | E39: 4 | F39: 191 | G39: =IFERROR(E39/F39," ") -> 0.020942408 | H39: No
A40: Simplicity: The Freedom of Letting Go | B40: y | D40: Book | E40: 4 | F40: 192 | G40: =IFERROR(E40/F40," ") -> 0.020833333 | H40: No
...

Sheet Read
A1: Book Ranking
A2: Title | B2: Value | C2: Page Numbers | D2: Result | E2: Read
A3: =Unread!A3 -> The Rubaiyat | B3: =Unread!E3 -> 4 | C3: =Unread!F3 -> 46 | D3: =Unread!G3 -> 0.086956522 | E3: =Unread!H3 -> Yes
A4: =Unread!A4 -> World War I at Home | B4: =Unread!E4 -> 2 | C4: =Unread!F4 -> 0 | D4: =Unread!G4 | E4: =Unread!H4 -> No
A5: =Unread!A5 -> World War I (Baldwin) | B5: =Unread!E5 -> 2 | C5: =Unread!F5 -> 0 | D5: =Unread!G5 | E5: =Unread!H5 -> No
A6: =Unread!A6 -> Cavalry of the Clouds | B6: =Unread!E6 -> 2 | C6: =Unread!F6 -> 0 | D6: =Unread!G6 | E6: =Unread!H6 -> No
A7: =Unread!A7 -> Undertones of War | B7: =Unread!E7 -> 2 | C7: =Unread!F7 -> 0 | D7: =Unread!G7 | E7: =Unread!H7 -> No
A8: =Unread!A8 -> Sinking of the Titanic | B8: =Unread!E8 -> 2 | C8: =Unread!F8 -> 0 | D8: =Unread!G8 | E8: =Unread!H8 -> No
A9: =Unread!A9 -> History of the World War (March) | B9: =Unread!E9 -> 2 | C9: =Unread!F9 -> 0 | D9: =Unread!G9 | E9: =Unread!H9 -> No
A10: =Unread!A10 -> World War for Humanity | B10: =Unread!E10 -> 2 | C10: =Unread!F10 -> 0 | D10: =Unread!G10 | E10: =Unread!H10 -> No
A11: =Unread!A11 -> School for Soldiers | B11: =Unread!E11 -> 2 | C11: =Unread!F11 -> 0 | D11: =Unread!G11 | E11: =Unread!H11 -> No
A12: =Unread!A12 -> The First World War (Strachan) | B12: =Unread!E12 -> 2 | C12: =Unread!F12 -> 0 | D12: =Unread!G12 | E12: =Unread!H12 -> No
A13: =Unread!A13 -> Soldier from the Wars Returning (Carrington) | B13: =Unread!E13 -> 2 | C13: =Unread!F13 -> 0 | D13: =Unread!G13 | E13: =Unread!H13 -> No
A14: =Unread!A14 -> Randomness and Mathematical Proof (Report) | B14: =Unread!E14 -> 4 | C14: =Unread!F14 -> 9 | D14: =Unread!G14 -> 0.44444444 | E14: =Unread!H14 -> Yes
... A129: =Unread!A129 -> Enemies: A History of the FBI | B129: =Unread!E129 -> 3 | C129: =Unread!F129 -> 560 | D129: =Unread!G129 -> 0.0053571429 | E129: =Unread!H129 -> No
A130: =unread!#ref! -> #NAME? | B130: =unread!#ref! -> #NAME? | C130: =unread!#ref! -> #NAME? | D130: =unread!#ref! -> #NAME? | E130: =unread!#ref! -> #NAME?
A131: =unread!#ref! -> #NAME? | B131: =unread!#ref! -> #NAME? | C131: =unread!#ref! -> #NAME? | D131: =unread!#ref! -> #NAME? | E131: =unread!#ref! -> #NAME?

Sheet Dropdown
A1: Book Read | C1: Media
A2: Yes | C2: Book
A3: No | C3: Research Paper
A4: Yes (Reading Again) | C4: Online Article
C5: Wikipedia
C6: Book
C7: Online Text
